2020-05-14 13:15:36,583 - root - INFO - Started
2020-05-14 15:37:52,729 - root - ERROR - Traceback (most recent call last):
  File "train/train_wsi_on_512x1x1_pretrained.py", line 133, in <module>
    trainer.fit(module, train_loader, val_loader)
  File "/home/ruslan/anaconda3/lib/python3.7/site-packages/pytorch_lightning/trainer/trainer.py", line 758, in fit
    self.single_gpu_train(model)
  File "/home/ruslan/anaconda3/lib/python3.7/site-packages/pytorch_lightning/trainer/distrib_parts.py", line 492, in single_gpu_train
    self.run_pretrain_routine(model)
  File "/home/ruslan/anaconda3/lib/python3.7/site-packages/pytorch_lightning/trainer/trainer.py", line 906, in run_pretrain_routine
    self.train()
  File "/home/ruslan/anaconda3/lib/python3.7/site-packages/pytorch_lightning/trainer/training_loop.py", line 350, in train
    self.run_training_epoch()
  File "/home/ruslan/anaconda3/lib/python3.7/site-packages/pytorch_lightning/trainer/training_loop.py", line 468, in run_training_epoch
    self.log_metrics(batch_step_metrics, grad_norm_dic)
  File "/home/ruslan/anaconda3/lib/python3.7/site-packages/pytorch_lightning/trainer/logging.py", line 74, in log_metrics
    self.logger.save()
  File "/home/ruslan/anaconda3/lib/python3.7/site-packages/pytorch_lightning/utilities/distributed.py", line 10, in wrapped_fn
    return fn(*args, **kwargs)
  File "/home/ruslan/anaconda3/lib/python3.7/site-packages/pytorch_lightning/loggers/tensorboard.py", line 150, in save
    with open(meta_tags_path, 'w', newline='') as csvfile:
FileNotFoundError: [Errno 2] No such file or directory: 'experiments_results/wsi_on_dummy_512x1x1/meta_tags.csv'

