2020-05-16 00:21:10,943 - root - INFO - Started
2020-05-16 00:21:10,945 - root - ERROR - Traceback (most recent call last):
  File "train/train_wsi_on_512x1x1_pretrained.py", line 55, in <module>
    import_module(f'experiments_configs.{exp_subfolder}.{exp_name}')
  File "/home/ruslan/anaconda3/lib/python3.7/importlib/__init__.py", line 127, in import_module
    return _bootstrap._gcd_import(name[level:], package, level)
  File "<frozen importlib._bootstrap>", line 1006, in _gcd_import
  File "<frozen importlib._bootstrap>", line 983, in _find_and_load
  File "<frozen importlib._bootstrap>", line 967, in _find_and_load_unlocked
  File "<frozen importlib._bootstrap>", line 677, in _load_unlocked
  File "<frozen importlib._bootstrap_external>", line 728, in exec_module
  File "<frozen importlib._bootstrap>", line 219, in _call_with_frames_removed
  File "/home/ruslan/notebooks/pcancer/experiments_configs/wsi_on_dummy_512x1x1/450ep_adam_cos_an2_do02.py", line 17, in <module>
    'classes': max_lbl_nums,
NameError: name 'max_lbl_nums' is not defined

